cannot convert KDE_FULL_SESSION argument to STRING or COMPOUND_TEXT.
kdeinit5: preparing to launch '/usr/lib/kf5/klauncher'
kdeinit5: Launched KLauncher, pid = 2686, result = 0
kdeinit5: opened connection to :0
kdeinit5: Got SETENV 'XCURSOR_THEME=Sweet-cursors' from launcher.
kdeinit5: Got SETENV 'XCURSOR_SIZE=24' from launcher.
kdeinit5: Got SETENV 'GTK_RC_FILES=/etc/gtk/gtkrc:/home/shivakantm/.gtkrc:/home/shivakantm/.config/gtkrc' from launcher.
kdeinit5: Got SETENV 'GTK2_RC_FILES=/etc/gtk-2.0/gtkrc:/home/shivakantm/.gtkrc-2.0:/home/shivakantm/.config/gtkrc-2.0' from launcher.
kdeinit5: Got SETENV 'SESSION_MANAGER=local/shivakant-hppavilionx360convertible14dh1xxx:@/tmp/.ICE-unix/2763,unix/shivakant-hppavilionx360convertible14dh1xxx:/tmp/.ICE-unix/2763' from launcher.
kdeinit5: Got SETENV 'SESSION_MANAGER=local/shivakant-hppavilionx360convertible14dh1xxx:@/tmp/.ICE-unix/2763,unix/shivakant-hppavilionx360convertible14dh1xxx:/tmp/.ICE-unix/2763' from launcher.
conky: no personal or system-wide config file found, using builtin default
Failed to load profile 'default': Profile not found (line 1420)
Error: A JNI error has occurred, please check your installation and try again
Exception in thread "main" java.lang.UnsupportedClassVersionError: xdman/Main has been compiled by a more recent version of the Java Runtime (class file version 55.0), this version of the Java Runtime only recognizes class file versions up to 52.0
	at java.lang.ClassLoader.defineClass1(Native Method)
	at java.lang.ClassLoader.defineClass(ClassLoader.java:756)
	at java.security.SecureClassLoader.defineClass(SecureClassLoader.java:142)
	at java.net.URLClassLoader.defineClass(URLClassLoader.java:468)
	at java.net.URLClassLoader.access$100(URLClassLoader.java:74)
	at java.net.URLClassLoader$1.run(URLClassLoader.java:369)
	at java.net.URLClassLoader$1.run(URLClassLoader.java:363)
	at java.security.AccessController.doPrivileged(Native Method)
	at java.net.URLClassLoader.findClass(URLClassLoader.java:362)
	at java.lang.ClassLoader.loadClass(ClassLoader.java:418)
	at sun.misc.Launcher$AppClassLoader.loadClass(Launcher.java:352)
	at java.lang.ClassLoader.loadClass(ClassLoader.java:351)
	at sun.launcher.LauncherHelper.checkAndLoadMain(LauncherHelper.java:601)
conky: desktop window (400018) is subwindow of root window (19f)
conky: window type - desktop
conky: drawing to created window (0x3c00001)
conky: drawing to double buffer
conky: forked to background, pid is 3021

(variety:2835): Gtk-WARNING **: 08:38:13.979: Theme parsing error: gtk-dark.css:6342:10: 'height' is not a valid property name


(evolution-alarm-notify:2839): Gtk-WARNING **: 08:38:14.125: Theme parsing error: gtk-dark.css:6342:10: 'height' is not a valid property name
kdeinit5: Got EXEC_NEW '/usr/lib/qt/plugins/kf5/kio/desktop.so' from launcher.
kdeinit5: preparing to launch '/usr/lib/qt/plugins/kf5/kio/desktop.so'
kdeinit5: Got EXEC_NEW '/usr/lib/qt/plugins/kf5/kio/file.so' from launcher.
kdeinit5: preparing to launch '/usr/lib/qt/plugins/kf5/kio/file.so'
kdeinit5: Got EXEC_NEW '/usr/lib/qt/plugins/kf5/kio/file.so' from launcher.
kdeinit5: preparing to launch '/usr/lib/qt/plugins/kf5/kio/file.so'

(timeshift-gtk:3245): Gtk-WARNING **: 08:38:22.400: Theme parsing error: gtk-dark.css:6342:10: 'height' is not a valid property name

** (timeshift-gtk:3245): WARNING **: 08:38:22.425: Unable to connect to dbus: Error spawning command line “dbus-launch --autolaunch=145ec74cb0154f07b460d475522b9a0c --binary-syntax --close-stderr”: Child process exited with code 1

(timeshift-gtk:3245): GLib-GIO-CRITICAL **: 08:38:22.672: g_dbus_connection_register_object: assertion 'G_IS_DBUS_CONNECTION (connection)' failed

(timeshift-gtk:3245): GLib-GIO-CRITICAL **: 08:38:22.672: g_dbus_connection_register_object: assertion 'G_IS_DBUS_CONNECTION (connection)' failed

(timeshift-gtk:3245): GLib-GIO-CRITICAL **: 08:38:22.672: g_dbus_connection_get_unique_name: assertion 'G_IS_DBUS_CONNECTION (connection)' failed
WARNING: 2021-04-27 08:38:32,679: load_history() 'Could not load history file, continuing without it, no worries'
ERROR: 2021-04-27 08:38:32,752: download_one_from() 'Could not download wallpaper:'
Traceback (most recent call last):
  File "/usr/lib/python3.9/site-packages/urllib3/connection.py", line 169, in _new_conn
    conn = connection.create_connection(
  File "/usr/lib/python3.9/site-packages/urllib3/util/connection.py", line 73, in create_connection
    for res in socket.getaddrinfo(host, port, family, socket.SOCK_STREAM):
  File "/usr/lib/python3.9/socket.py", line 953, in getaddrinfo
    for res in _socket.getaddrinfo(host, port, family, type, proto, flags):
socket.gaierror: [Errno -2] Name or service not known

During handling of the above exception, another exception occurred:

Traceback (most recent call last):
  File "/usr/lib/python3.9/site-packages/urllib3/connectionpool.py", line 699, in urlopen
    httplib_response = self._make_request(
  File "/usr/lib/python3.9/site-packages/urllib3/connectionpool.py", line 382, in _make_request
    self._validate_conn(conn)
  File "/usr/lib/python3.9/site-packages/urllib3/connectionpool.py", line 1010, in _validate_conn
    conn.connect()
  File "/usr/lib/python3.9/site-packages/urllib3/connection.py", line 353, in connect
    conn = self._new_conn()
  File "/usr/lib/python3.9/site-packages/urllib3/connection.py", line 181, in _new_conn
    raise NewConnectionError(
urllib3.exceptions.NewConnectionError: <urllib3.connection.HTTPSConnection object at 0x7f8b1e2754f0>: Failed to establish a new connection: [Errno -2] Name or service not known

During handling of the above exception, another exception occurred:

Traceback (most recent call last):
  File "/usr/lib/python3.9/site-packages/requests/adapters.py", line 439, in send
    resp = conn.urlopen(
  File "/usr/lib/python3.9/site-packages/urllib3/connectionpool.py", line 755, in urlopen
    retries = retries.increment(
  File "/usr/lib/python3.9/site-packages/urllib3/util/retry.py", line 574, in increment
    raise MaxRetryError(_pool, url, error or ResponseError(cause))
urllib3.exceptions.MaxRetryError: HTTPSConnectionPool(host='www.bing.com', port=443): Max retries exceeded with url: /HPImageArchive.aspx?format=js&idx=0&n=100&mkt=en-US (Caused by NewConnectionError('<urllib3.connection.HTTPSConnection object at 0x7f8b1e2754f0>: Failed to establish a new connection: [Errno -2] Name or service not known'))

During handling of the above exception, another exception occurred:

Traceback (most recent call last):
  File "/usr/lib/python3.9/site-packages/variety/VarietyWindow.py", line 1160, in download_one_from
    file = downloader.download_one()
  File "/usr/lib/python3.9/site-packages/variety/plugins/downloaders/DefaultDownloader.py", line 141, in download_one
    items = self.fill_queue()
  File "/usr/lib/python3.9/site-packages/variety/plugins/builtin/downloaders/BingDownloader.py", line 61, in fill_queue
    s = Util.fetch_json(BingDownloader.BING_JSON_URL)
  File "/usr/lib/python3.9/site-packages/variety/Util.py", line 644, in fetch_json
    return Util.request(url, data, **request_kwargs).json()
  File "/usr/lib/python3.9/site-packages/variety/Util.py", line 614, in request
    r = requests.request(
  File "/usr/lib/python3.9/site-packages/requests/api.py", line 61, in request
    return session.request(method=method, url=url, **kwargs)
  File "/usr/lib/python3.9/site-packages/requests/sessions.py", line 542, in request
    resp = self.send(prep, **send_kwargs)
  File "/usr/lib/python3.9/site-packages/requests/sessions.py", line 655, in send
    r = adapter.send(request, **kwargs)
  File "/usr/lib/python3.9/site-packages/requests/adapters.py", line 516, in send
    raise ConnectionError(e, request=request)
requests.exceptions.ConnectionError: HTTPSConnectionPool(host='www.bing.com', port=443): Max retries exceeded with url: /HPImageArchive.aspx?format=js&idx=0&n=100&mkt=en-US (Caused by NewConnectionError('<urllib3.connection.HTTPSConnection object at 0x7f8b1e2754f0>: Failed to establish a new connection: [Errno -2] Name or service not known'))
WARNING: 2021-04-27 08:38:32,759: create_menu() 'Variety Slideshow is not installed. This is an optional extension adding pan-and-zoom slideshows to Variety: see https://github.com/peterlevi/variety-slideshow for details'
ERROR: 2021-04-27 08:38:33,761: download_one_from() 'Could not download wallpaper:'
Traceback (most recent call last):
  File "/usr/lib/python3.9/site-packages/urllib3/connection.py", line 169, in _new_conn
    conn = connection.create_connection(
  File "/usr/lib/python3.9/site-packages/urllib3/util/connection.py", line 73, in create_connection
    for res in socket.getaddrinfo(host, port, family, socket.SOCK_STREAM):
  File "/usr/lib/python3.9/socket.py", line 953, in getaddrinfo
    for res in _socket.getaddrinfo(host, port, family, type, proto, flags):
socket.gaierror: [Errno -2] Name or service not known

During handling of the above exception, another exception occurred:

Traceback (most recent call last):
  File "/usr/lib/python3.9/site-packages/urllib3/connectionpool.py", line 699, in urlopen
    httplib_response = self._make_request(
  File "/usr/lib/python3.9/site-packages/urllib3/connectionpool.py", line 382, in _make_request
    self._validate_conn(conn)
  File "/usr/lib/python3.9/site-packages/urllib3/connectionpool.py", line 1010, in _validate_conn
    conn.connect()
  File "/usr/lib/python3.9/site-packages/urllib3/connection.py", line 353, in connect
    conn = self._new_conn()
  File "/usr/lib/python3.9/site-packages/urllib3/connection.py", line 181, in _new_conn
    raise NewConnectionError(
urllib3.exceptions.NewConnectionError: <urllib3.connection.HTTPSConnection object at 0x7f8b1c08d970>: Failed to establish a new connection: [Errno -2] Name or service not known

During handling of the above exception, another exception occurred:

Traceback (most recent call last):
  File "/usr/lib/python3.9/site-packages/requests/adapters.py", line 439, in send
    resp = conn.urlopen(
  File "/usr/lib/python3.9/site-packages/urllib3/connectionpool.py", line 755, in urlopen
    retries = retries.increment(
  File "/usr/lib/python3.9/site-packages/urllib3/util/retry.py", line 574, in increment
    raise MaxRetryError(_pool, url, error or ResponseError(cause))
urllib3.exceptions.MaxRetryError: HTTPSConnectionPool(host='api.unsplash.com', port=443): Max retries exceeded with url: /photos/random?count=30&client_id=072e5048dfcb73a8d9ad59fcf402471518ff8df725df462b0c4fa665f466515a&orientation=landscape (Caused by NewConnectionError('<urllib3.connection.HTTPSConnection object at 0x7f8b1c08d970>: Failed to establish a new connection: [Errno -2] Name or service not known'))

During handling of the above exception, another exception occurred:

Traceback (most recent call last):
  File "/usr/lib/python3.9/site-packages/variety/VarietyWindow.py", line 1160, in download_one_from
    file = downloader.download_one()
  File "/usr/lib/python3.9/site-packages/variety/plugins/downloaders/DefaultDownloader.py", line 141, in download_one
    items = self.fill_queue()
  File "/usr/lib/python3.9/site-packages/variety/plugins/builtin/downloaders/UnsplashDownloader.py", line 87, in fill_queue
    r = Util.request(url)
  File "/usr/lib/python3.9/site-packages/variety/Util.py", line 614, in request
    r = requests.request(
  File "/usr/lib/python3.9/site-packages/requests/api.py", line 61, in request
    return session.request(method=method, url=url, **kwargs)
  File "/usr/lib/python3.9/site-packages/requests/sessions.py", line 542, in request
    resp = self.send(prep, **send_kwargs)
  File "/usr/lib/python3.9/site-packages/requests/sessions.py", line 655, in send
    r = adapter.send(request, **kwargs)
  File "/usr/lib/python3.9/site-packages/requests/adapters.py", line 516, in send
    raise ConnectionError(e, request=request)
requests.exceptions.ConnectionError: HTTPSConnectionPool(host='api.unsplash.com', port=443): Max retries exceeded with url: /photos/random?count=30&client_id=072e5048dfcb73a8d9ad59fcf402471518ff8df725df462b0c4fa665f466515a&orientation=landscape (Caused by NewConnectionError('<urllib3.connection.HTTPSConnection object at 0x7f8b1c08d970>: Failed to establish a new connection: [Errno -2] Name or service not known'))
ERROR: 2021-04-27 08:38:34,765: download_one_from() 'Could not download wallpaper:'
Traceback (most recent call last):
  File "/usr/lib/python3.9/site-packages/urllib3/connection.py", line 169, in _new_conn
    conn = connection.create_connection(
  File "/usr/lib/python3.9/site-packages/urllib3/util/connection.py", line 73, in create_connection
    for res in socket.getaddrinfo(host, port, family, socket.SOCK_STREAM):
  File "/usr/lib/python3.9/socket.py", line 953, in getaddrinfo
    for res in _socket.getaddrinfo(host, port, family, type, proto, flags):
socket.gaierror: [Errno -2] Name or service not known

During handling of the above exception, another exception occurred:

Traceback (most recent call last):
  File "/usr/lib/python3.9/site-packages/urllib3/connectionpool.py", line 699, in urlopen
    httplib_response = self._make_request(
  File "/usr/lib/python3.9/site-packages/urllib3/connectionpool.py", line 394, in _make_request
    conn.request(method, url, **httplib_request_kw)
  File "/usr/lib/python3.9/site-packages/urllib3/connection.py", line 234, in request
    super(HTTPConnection, self).request(method, url, body=body, headers=headers)
  File "/usr/lib/python3.9/http/client.py", line 1253, in request
    self._send_request(method, url, body, headers, encode_chunked)
  File "/usr/lib/python3.9/http/client.py", line 1299, in _send_request
    self.endheaders(body, encode_chunked=encode_chunked)
  File "/usr/lib/python3.9/http/client.py", line 1248, in endheaders
    self._send_output(message_body, encode_chunked=encode_chunked)
  File "/usr/lib/python3.9/http/client.py", line 1008, in _send_output
    self.send(msg)
  File "/usr/lib/python3.9/http/client.py", line 948, in send
    self.connect()
  File "/usr/lib/python3.9/site-packages/urllib3/connection.py", line 200, in connect
    conn = self._new_conn()
  File "/usr/lib/python3.9/site-packages/urllib3/connection.py", line 181, in _new_conn
    raise NewConnectionError(
urllib3.exceptions.NewConnectionError: <urllib3.connection.HTTPConnection object at 0x7f8b1c08db20>: Failed to establish a new connection: [Errno -2] Name or service not known

During handling of the above exception, another exception occurred:

Traceback (most recent call last):
  File "/usr/lib/python3.9/site-packages/requests/adapters.py", line 439, in send
    resp = conn.urlopen(
  File "/usr/lib/python3.9/site-packages/urllib3/connectionpool.py", line 755, in urlopen
    retries = retries.increment(
  File "/usr/lib/python3.9/site-packages/urllib3/util/retry.py", line 574, in increment
    raise MaxRetryError(_pool, url, error or ResponseError(cause))
urllib3.exceptions.MaxRetryError: HTTPConnectionPool(host='apod.nasa.gov', port=80): Max retries exceeded with url: /apod/archivepix.html (Caused by NewConnectionError('<urllib3.connection.HTTPConnection object at 0x7f8b1c08db20>: Failed to establish a new connection: [Errno -2] Name or service not known'))

During handling of the above exception, another exception occurred:

Traceback (most recent call last):
  File "/usr/lib/python3.9/site-packages/variety/VarietyWindow.py", line 1160, in download_one_from
    file = downloader.download_one()
  File "/usr/lib/python3.9/site-packages/variety/plugins/downloaders/DefaultDownloader.py", line 141, in download_one
    items = self.fill_queue()
  File "/usr/lib/python3.9/site-packages/variety/plugins/builtin/downloaders/APODDownloader.py", line 59, in fill_queue
    s = Util.html_soup(self.ROOT_URL + "archivepix.html")
  File "/usr/lib/python3.9/site-packages/variety/Util.py", line 648, in html_soup
    return bs4.BeautifulSoup(Util.fetch(url, data, **request_kwargs), "lxml")
  File "/usr/lib/python3.9/site-packages/variety/Util.py", line 636, in fetch
    return Util.request(url, data, **request_kwargs).text
  File "/usr/lib/python3.9/site-packages/variety/Util.py", line 614, in request
    r = requests.request(
  File "/usr/lib/python3.9/site-packages/requests/api.py", line 61, in request
    return session.request(method=method, url=url, **kwargs)
  File "/usr/lib/python3.9/site-packages/requests/sessions.py", line 542, in request
    resp = self.send(prep, **send_kwargs)
  File "/usr/lib/python3.9/site-packages/requests/sessions.py", line 655, in send
    r = adapter.send(request, **kwargs)
  File "/usr/lib/python3.9/site-packages/requests/adapters.py", line 516, in send
    raise ConnectionError(e, request=request)
requests.exceptions.ConnectionError: HTTPConnectionPool(host='apod.nasa.gov', port=80): Max retries exceeded with url: /apod/archivepix.html (Caused by NewConnectionError('<urllib3.connection.HTTPConnection object at 0x7f8b1c08db20>: Failed to establish a new connection: [Errno -2] Name or service not known'))
ERROR: 2021-04-27 08:38:35,769: download_one_from() 'Could not download wallpaper:'
Traceback (most recent call last):
  File "/usr/lib/python3.9/site-packages/urllib3/connection.py", line 169, in _new_conn
    conn = connection.create_connection(
  File "/usr/lib/python3.9/site-packages/urllib3/util/connection.py", line 73, in create_connection
    for res in socket.getaddrinfo(host, port, family, socket.SOCK_STREAM):
  File "/usr/lib/python3.9/socket.py", line 953, in getaddrinfo
    for res in _socket.getaddrinfo(host, port, family, type, proto, flags):
socket.gaierror: [Errno -2] Name or service not known

During handling of the above exception, another exception occurred:

Traceback (most recent call last):
  File "/usr/lib/python3.9/site-packages/urllib3/connectionpool.py", line 699, in urlopen
    httplib_response = self._make_request(
  File "/usr/lib/python3.9/site-packages/urllib3/connectionpool.py", line 382, in _make_request
    self._validate_conn(conn)
  File "/usr/lib/python3.9/site-packages/urllib3/connectionpool.py", line 1010, in _validate_conn
    conn.connect()
  File "/usr/lib/python3.9/site-packages/urllib3/connection.py", line 353, in connect
    conn = self._new_conn()
  File "/usr/lib/python3.9/site-packages/urllib3/connection.py", line 181, in _new_conn
    raise NewConnectionError(
urllib3.exceptions.NewConnectionError: <urllib3.connection.HTTPSConnection object at 0x7f8b1c08dca0>: Failed to establish a new connection: [Errno -2] Name or service not known

During handling of the above exception, another exception occurred:

Traceback (most recent call last):
  File "/usr/lib/python3.9/site-packages/requests/adapters.py", line 439, in send
    resp = conn.urlopen(
  File "/usr/lib/python3.9/site-packages/urllib3/connectionpool.py", line 755, in urlopen
    retries = retries.increment(
  File "/usr/lib/python3.9/site-packages/urllib3/util/retry.py", line 574, in increment
    raise MaxRetryError(_pool, url, error or ResponseError(cause))
urllib3.exceptions.MaxRetryError: HTTPSConnectionPool(host='api.flickr.com', port=443): Max retries exceeded with url: /services/rest/?method=flickr.photos.search&api_key=0553a848c09bcfd21d3a984d9408c04e&per_page=500&tag_mode=all&format=json&nojsoncallback=1&user_id=93647178@N00 (Caused by NewConnectionError('<urllib3.connection.HTTPSConnection object at 0x7f8b1c08dca0>: Failed to establish a new connection: [Errno -2] Name or service not known'))

During handling of the above exception, another exception occurred:

Traceback (most recent call last):
  File "/usr/lib/python3.9/site-packages/variety/VarietyWindow.py", line 1160, in download_one_from
    file = downloader.download_one()
  File "/usr/lib/python3.9/site-packages/variety/plugins/downloaders/DefaultDownloader.py", line 141, in download_one
    items = self.fill_queue()
  File "/usr/lib/python3.9/site-packages/variety/FlickrDownloader.py", line 161, in fill_queue
    resp = FlickrDownloader.fetch(call)
  File "/usr/lib/python3.9/site-packages/variety/FlickrDownloader.py", line 74, in fetch
    return Util.fetch_json(call)
  File "/usr/lib/python3.9/site-packages/variety/Util.py", line 644, in fetch_json
    return Util.request(url, data, **request_kwargs).json()
  File "/usr/lib/python3.9/site-packages/variety/Util.py", line 614, in request
    r = requests.request(
  File "/usr/lib/python3.9/site-packages/requests/api.py", line 61, in request
    return session.request(method=method, url=url, **kwargs)
  File "/usr/lib/python3.9/site-packages/requests/sessions.py", line 542, in request
    resp = self.send(prep, **send_kwargs)
  File "/usr/lib/python3.9/site-packages/requests/sessions.py", line 655, in send
    r = adapter.send(request, **kwargs)
  File "/usr/lib/python3.9/site-packages/requests/adapters.py", line 516, in send
    raise ConnectionError(e, request=request)
requests.exceptions.ConnectionError: HTTPSConnectionPool(host='api.flickr.com', port=443): Max retries exceeded with url: /services/rest/?method=flickr.photos.search&api_key=0553a848c09bcfd21d3a984d9408c04e&per_page=500&tag_mode=all&format=json&nojsoncallback=1&user_id=93647178@N00 (Caused by NewConnectionError('<urllib3.connection.HTTPSConnection object at 0x7f8b1c08dca0>: Failed to establish a new connection: [Errno -2] Name or service not known'))
ERROR: 2021-04-27 08:38:36,772: download_one_from() 'Could not download wallpaper:'
Traceback (most recent call last):
  File "/usr/lib/python3.9/site-packages/urllib3/connection.py", line 169, in _new_conn
    conn = connection.create_connection(
  File "/usr/lib/python3.9/site-packages/urllib3/util/connection.py", line 73, in create_connection
    for res in socket.getaddrinfo(host, port, family, socket.SOCK_STREAM):
  File "/usr/lib/python3.9/socket.py", line 953, in getaddrinfo
    for res in _socket.getaddrinfo(host, port, family, type, proto, flags):
socket.gaierror: [Errno -2] Name or service not known

During handling of the above exception, another exception occurred:

Traceback (most recent call last):
  File "/usr/lib/python3.9/site-packages/urllib3/connectionpool.py", line 699, in urlopen
    httplib_response = self._make_request(
  File "/usr/lib/python3.9/site-packages/urllib3/connectionpool.py", line 382, in _make_request
    self._validate_conn(conn)
  File "/usr/lib/python3.9/site-packages/urllib3/connectionpool.py", line 1010, in _validate_conn
    conn.connect()
  File "/usr/lib/python3.9/site-packages/urllib3/connection.py", line 353, in connect
    conn = self._new_conn()
  File "/usr/lib/python3.9/site-packages/urllib3/connection.py", line 181, in _new_conn
    raise NewConnectionError(
urllib3.exceptions.NewConnectionError: <urllib3.connection.HTTPSConnection object at 0x7f8af2654070>: Failed to establish a new connection: [Errno -2] Name or service not known

During handling of the above exception, another exception occurred:

Traceback (most recent call last):
  File "/usr/lib/python3.9/site-packages/requests/adapters.py", line 439, in send
    resp = conn.urlopen(
  File "/usr/lib/python3.9/site-packages/urllib3/connectionpool.py", line 755, in urlopen
    retries = retries.increment(
  File "/usr/lib/python3.9/site-packages/urllib3/util/retry.py", line 574, in increment
    raise MaxRetryError(_pool, url, error or ResponseError(cause))
urllib3.exceptions.MaxRetryError: HTTPSConnectionPool(host='raw.githubusercontent.com', port=443): Max retries exceeded with url: /limhenry/earthview/3cd868a932cd652c4373c0f6ea8618a96b08be4e/wallpaper%20changer/data.json (Caused by NewConnectionError('<urllib3.connection.HTTPSConnection object at 0x7f8af2654070>: Failed to establish a new connection: [Errno -2] Name or service not known'))

During handling of the above exception, another exception occurred:

Traceback (most recent call last):
  File "/usr/lib/python3.9/site-packages/variety/VarietyWindow.py", line 1160, in download_one_from
    file = downloader.download_one()
  File "/usr/lib/python3.9/site-packages/variety/plugins/downloaders/DefaultDownloader.py", line 141, in download_one
    items = self.fill_queue()
  File "/usr/lib/python3.9/site-packages/variety/plugins/builtin/downloaders/EarthviewDownloader.py", line 57, in fill_queue
    queue = Util.fetch_json(DATA_URL)
  File "/usr/lib/python3.9/site-packages/variety/Util.py", line 644, in fetch_json
    return Util.request(url, data, **request_kwargs).json()
  File "/usr/lib/python3.9/site-packages/variety/Util.py", line 614, in request
    r = requests.request(
  File "/usr/lib/python3.9/site-packages/requests/api.py", line 61, in request
    return session.request(method=method, url=url, **kwargs)
  File "/usr/lib/python3.9/site-packages/requests/sessions.py", line 542, in request
    resp = self.send(prep, **send_kwargs)
  File "/usr/lib/python3.9/site-packages/requests/sessions.py", line 655, in send
    r = adapter.send(request, **kwargs)
  File "/usr/lib/python3.9/site-packages/requests/adapters.py", line 516, in send
    raise ConnectionError(e, request=request)
requests.exceptions.ConnectionError: HTTPSConnectionPool(host='raw.githubusercontent.com', port=443): Max retries exceeded with url: /limhenry/earthview/3cd868a932cd652c4373c0f6ea8618a96b08be4e/wallpaper%20changer/data.json (Caused by NewConnectionError('<urllib3.connection.HTTPSConnection object at 0x7f8af2654070>: Failed to establish a new connection: [Errno -2] Name or service not known'))
ERROR: 2021-04-27 08:38:52,747: server_options_thread() 'Could not fetch Variety serverside options'
Traceback (most recent call last):
  File "/usr/lib/python3.9/site-packages/urllib3/connection.py", line 169, in _new_conn
    conn = connection.create_connection(
  File "/usr/lib/python3.9/site-packages/urllib3/util/connection.py", line 73, in create_connection
    for res in socket.getaddrinfo(host, port, family, socket.SOCK_STREAM):
  File "/usr/lib/python3.9/socket.py", line 953, in getaddrinfo
    for res in _socket.getaddrinfo(host, port, family, type, proto, flags):
socket.gaierror: [Errno -2] Name or service not known

During handling of the above exception, another exception occurred:

Traceback (most recent call last):
  File "/usr/lib/python3.9/site-packages/urllib3/connectionpool.py", line 699, in urlopen
    httplib_response = self._make_request(
  File "/usr/lib/python3.9/site-packages/urllib3/connectionpool.py", line 394, in _make_request
    conn.request(method, url, **httplib_request_kw)
  File "/usr/lib/python3.9/site-packages/urllib3/connection.py", line 234, in request
    super(HTTPConnection, self).request(method, url, body=body, headers=headers)
  File "/usr/lib/python3.9/http/client.py", line 1253, in request
    self._send_request(method, url, body, headers, encode_chunked)
  File "/usr/lib/python3.9/http/client.py", line 1299, in _send_request
    self.endheaders(body, encode_chunked=encode_chunked)
  File "/usr/lib/python3.9/http/client.py", line 1248, in endheaders
    self._send_output(message_body, encode_chunked=encode_chunked)
  File "/usr/lib/python3.9/http/client.py", line 1008, in _send_output
    self.send(msg)
  File "/usr/lib/python3.9/http/client.py", line 948, in send
    self.connect()
  File "/usr/lib/python3.9/site-packages/urllib3/connection.py", line 200, in connect
    conn = self._new_conn()
  File "/usr/lib/python3.9/site-packages/urllib3/connection.py", line 181, in _new_conn
    raise NewConnectionError(
urllib3.exceptions.NewConnectionError: <urllib3.connection.HTTPConnection object at 0x7f8af26b9100>: Failed to establish a new connection: [Errno -2] Name or service not known

During handling of the above exception, another exception occurred:

Traceback (most recent call last):
  File "/usr/lib/python3.9/site-packages/requests/adapters.py", line 439, in send
    resp = conn.urlopen(
  File "/usr/lib/python3.9/site-packages/urllib3/connectionpool.py", line 755, in urlopen
    retries = retries.increment(
  File "/usr/lib/python3.9/site-packages/urllib3/util/retry.py", line 574, in increment
    raise MaxRetryError(_pool, url, error or ResponseError(cause))
urllib3.exceptions.MaxRetryError: HTTPConnectionPool(host='tiny.cc', port=80): Max retries exceeded with url: /variety-options-063 (Caused by NewConnectionError('<urllib3.connection.HTTPConnection object at 0x7f8af26b9100>: Failed to establish a new connection: [Errno -2] Name or service not known'))

During handling of the above exception, another exception occurred:

Traceback (most recent call last):
  File "/usr/lib/python3.9/site-packages/variety/VarietyWindow.py", line 1086, in server_options_thread
    self.server_options = Util.fetch_json(VarietyWindow.SERVERSIDE_OPTIONS_URL)
  File "/usr/lib/python3.9/site-packages/variety/Util.py", line 644, in fetch_json
    return Util.request(url, data, **request_kwargs).json()
  File "/usr/lib/python3.9/site-packages/variety/Util.py", line 614, in request
    r = requests.request(
  File "/usr/lib/python3.9/site-packages/requests/api.py", line 61, in request
    return session.request(method=method, url=url, **kwargs)
  File "/usr/lib/python3.9/site-packages/requests/sessions.py", line 542, in request
    resp = self.send(prep, **send_kwargs)
  File "/usr/lib/python3.9/site-packages/requests/sessions.py", line 655, in send
    r = adapter.send(request, **kwargs)
  File "/usr/lib/python3.9/site-packages/requests/adapters.py", line 516, in send
    raise ConnectionError(e, request=request)
requests.exceptions.ConnectionError: HTTPConnectionPool(host='tiny.cc', port=80): Max retries exceeded with url: /variety-options-063 (Caused by NewConnectionError('<urllib3.connection.HTTPConnection object at 0x7f8af26b9100>: Failed to establish a new connection: [Errno -2] Name or service not known'))

(timeshift-gtk:3245): GLib-GIO-CRITICAL **: 08:38:59.898: g_dbus_connection_register_object: assertion 'G_IS_DBUS_CONNECTION (connection)' failed

(timeshift-gtk:3245): GLib-GIO-CRITICAL **: 08:38:59.898: g_dbus_connection_register_object: assertion 'G_IS_DBUS_CONNECTION (connection)' failed

(timeshift-gtk:3245): GLib-GIO-CRITICAL **: 08:38:59.898: g_dbus_connection_get_unique_name: assertion 'G_IS_DBUS_CONNECTION (connection)' failed
ERROR: 2021-04-27 08:39:22,779: server_options_thread() 'Could not fetch Variety serverside options'
Traceback (most recent call last):
  File "/usr/lib/python3.9/site-packages/urllib3/connection.py", line 169, in _new_conn
    conn = connection.create_connection(
  File "/usr/lib/python3.9/site-packages/urllib3/util/connection.py", line 73, in create_connection
    for res in socket.getaddrinfo(host, port, family, socket.SOCK_STREAM):
  File "/usr/lib/python3.9/socket.py", line 953, in getaddrinfo
    for res in _socket.getaddrinfo(host, port, family, type, proto, flags):
socket.gaierror: [Errno -2] Name or service not known

During handling of the above exception, another exception occurred:

Traceback (most recent call last):
  File "/usr/lib/python3.9/site-packages/urllib3/connectionpool.py", line 699, in urlopen
    httplib_response = self._make_request(
  File "/usr/lib/python3.9/site-packages/urllib3/connectionpool.py", line 394, in _make_request
    conn.request(method, url, **httplib_request_kw)
  File "/usr/lib/python3.9/site-packages/urllib3/connection.py", line 234, in request
    super(HTTPConnection, self).request(method, url, body=body, headers=headers)
  File "/usr/lib/python3.9/http/client.py", line 1253, in request
    self._send_request(method, url, body, headers, encode_chunked)
  File "/usr/lib/python3.9/http/client.py", line 1299, in _send_request
    self.endheaders(body, encode_chunked=encode_chunked)
  File "/usr/lib/python3.9/http/client.py", line 1248, in endheaders
    self._send_output(message_body, encode_chunked=encode_chunked)
  File "/usr/lib/python3.9/http/client.py", line 1008, in _send_output
    self.send(msg)
  File "/usr/lib/python3.9/http/client.py", line 948, in send
    self.connect()
  File "/usr/lib/python3.9/site-packages/urllib3/connection.py", line 200, in connect
    conn = self._new_conn()
  File "/usr/lib/python3.9/site-packages/urllib3/connection.py", line 181, in _new_conn
    raise NewConnectionError(
urllib3.exceptions.NewConnectionError: <urllib3.connection.HTTPConnection object at 0x7f8af26b95e0>: Failed to establish a new connection: [Errno -2] Name or service not known

During handling of the above exception, another exception occurred:

Traceback (most recent call last):
  File "/usr/lib/python3.9/site-packages/requests/adapters.py", line 439, in send
    resp = conn.urlopen(
  File "/usr/lib/python3.9/site-packages/urllib3/connectionpool.py", line 755, in urlopen
    retries = retries.increment(
  File "/usr/lib/python3.9/site-packages/urllib3/util/retry.py", line 574, in increment
    raise MaxRetryError(_pool, url, error or ResponseError(cause))
urllib3.exceptions.MaxRetryError: HTTPConnectionPool(host='tiny.cc', port=80): Max retries exceeded with url: /variety-options-063 (Caused by NewConnectionError('<urllib3.connection.HTTPConnection object at 0x7f8af26b95e0>: Failed to establish a new connection: [Errno -2] Name or service not known'))

During handling of the above exception, another exception occurred:

Traceback (most recent call last):
  File "/usr/lib/python3.9/site-packages/variety/VarietyWindow.py", line 1086, in server_options_thread
    self.server_options = Util.fetch_json(VarietyWindow.SERVERSIDE_OPTIONS_URL)
  File "/usr/lib/python3.9/site-packages/variety/Util.py", line 644, in fetch_json
    return Util.request(url, data, **request_kwargs).json()
  File "/usr/lib/python3.9/site-packages/variety/Util.py", line 614, in request
    r = requests.request(
  File "/usr/lib/python3.9/site-packages/requests/api.py", line 61, in request
    return session.request(method=method, url=url, **kwargs)
  File "/usr/lib/python3.9/site-packages/requests/sessions.py", line 542, in request
    resp = self.send(prep, **send_kwargs)
  File "/usr/lib/python3.9/site-packages/requests/sessions.py", line 655, in send
    r = adapter.send(request, **kwargs)
  File "/usr/lib/python3.9/site-packages/requests/adapters.py", line 516, in send
    raise ConnectionError(e, request=request)
requests.exceptions.ConnectionError: HTTPConnectionPool(host='tiny.cc', port=80): Max retries exceeded with url: /variety-options-063 (Caused by NewConnectionError('<urllib3.connection.HTTPConnection object at 0x7f8af26b95e0>: Failed to establish a new connection: [Errno -2] Name or service not known'))
kdeinit5: Got EXEC_NEW '/usr/lib/qt/plugins/kf5/kio/tags.so' from launcher.
kdeinit5: preparing to launch '/usr/lib/qt/plugins/kf5/kio/tags.so'
kdeinit5: Got EXEC_NEW '/usr/lib/qt/plugins/kf5/kio/trash.so' from launcher.
kdeinit5: preparing to launch '/usr/lib/qt/plugins/kf5/kio/trash.so'
kdeinit5: Got EXEC_NEW '/usr/lib/qt/plugins/kf5/kio/file.so' from launcher.
kdeinit5: preparing to launch '/usr/lib/qt/plugins/kf5/kio/file.so'
kdeinit5: Got EXEC_NEW '/usr/lib/qt/plugins/kf5/kio/file.so' from launcher.
kdeinit5: preparing to launch '/usr/lib/qt/plugins/kf5/kio/file.so'
kdeinit5: Got EXEC_NEW '/usr/lib/qt/plugins/kf5/kio/file.so' from launcher.
kdeinit5: preparing to launch '/usr/lib/qt/plugins/kf5/kio/file.so'
kdeinit5: Got EXEC_NEW '/usr/lib/qt/plugins/kf5/kio/file.so' from launcher.
kdeinit5: preparing to launch '/usr/lib/qt/plugins/kf5/kio/file.so'
kdeinit5: Got EXEC_NEW '/usr/lib/qt/plugins/kf5/kio/thumbnail.so' from launcher.
kdeinit5: preparing to launch '/usr/lib/qt/plugins/kf5/kio/thumbnail.so'

(variety:2835): Gtk-WARNING **: 08:39:37.664: Failed to measure available space: The specified location is not supported
ERROR: 2021-04-27 08:39:52,809: server_options_thread() 'Could not fetch Variety serverside options'
Traceback (most recent call last):
  File "/usr/lib/python3.9/site-packages/urllib3/connection.py", line 169, in _new_conn
    conn = connection.create_connection(
  File "/usr/lib/python3.9/site-packages/urllib3/util/connection.py", line 73, in create_connection
    for res in socket.getaddrinfo(host, port, family, socket.SOCK_STREAM):
  File "/usr/lib/python3.9/socket.py", line 953, in getaddrinfo
    for res in _socket.getaddrinfo(host, port, family, type, proto, flags):
socket.gaierror: [Errno -2] Name or service not known

During handling of the above exception, another exception occurred:

Traceback (most recent call last):
  File "/usr/lib/python3.9/site-packages/urllib3/connectionpool.py", line 699, in urlopen
    httplib_response = self._make_request(
  File "/usr/lib/python3.9/site-packages/urllib3/connectionpool.py", line 394, in _make_request
    conn.request(method, url, **httplib_request_kw)
  File "/usr/lib/python3.9/site-packages/urllib3/connection.py", line 234, in request
    super(HTTPConnection, self).request(method, url, body=body, headers=headers)
  File "/usr/lib/python3.9/http/client.py", line 1253, in request
    self._send_request(method, url, body, headers, encode_chunked)
  File "/usr/lib/python3.9/http/client.py", line 1299, in _send_request
    self.endheaders(body, encode_chunked=encode_chunked)
  File "/usr/lib/python3.9/http/client.py", line 1248, in endheaders
    self._send_output(message_body, encode_chunked=encode_chunked)
  File "/usr/lib/python3.9/http/client.py", line 1008, in _send_output
    self.send(msg)
  File "/usr/lib/python3.9/http/client.py", line 948, in send
    self.connect()
  File "/usr/lib/python3.9/site-packages/urllib3/connection.py", line 200, in connect
    conn = self._new_conn()
  File "/usr/lib/python3.9/site-packages/urllib3/connection.py", line 181, in _new_conn
    raise NewConnectionError(
urllib3.exceptions.NewConnectionError: <urllib3.connection.HTTPConnection object at 0x7f8af26b9700>: Failed to establish a new connection: [Errno -2] Name or service not known

During handling of the above exception, another exception occurred:

Traceback (most recent call last):
  File "/usr/lib/python3.9/site-packages/requests/adapters.py", line 439, in send
    resp = conn.urlopen(
  File "/usr/lib/python3.9/site-packages/urllib3/connectionpool.py", line 755, in urlopen
    retries = retries.increment(
  File "/usr/lib/python3.9/site-packages/urllib3/util/retry.py", line 574, in increment
    raise MaxRetryError(_pool, url, error or ResponseError(cause))
urllib3.exceptions.MaxRetryError: HTTPConnectionPool(host='tiny.cc', port=80): Max retries exceeded with url: /variety-options-063 (Caused by NewConnectionError('<urllib3.connection.HTTPConnection object at 0x7f8af26b9700>: Failed to establish a new connection: [Errno -2] Name or service not known'))

During handling of the above exception, another exception occurred:

Traceback (most recent call last):
  File "/usr/lib/python3.9/site-packages/variety/VarietyWindow.py", line 1086, in server_options_thread
    self.server_options = Util.fetch_json(VarietyWindow.SERVERSIDE_OPTIONS_URL)
  File "/usr/lib/python3.9/site-packages/variety/Util.py", line 644, in fetch_json
    return Util.request(url, data, **request_kwargs).json()
  File "/usr/lib/python3.9/site-packages/variety/Util.py", line 614, in request
    r = requests.request(
  File "/usr/lib/python3.9/site-packages/requests/api.py", line 61, in request
    return session.request(method=method, url=url, **kwargs)
  File "/usr/lib/python3.9/site-packages/requests/sessions.py", line 542, in request
    resp = self.send(prep, **send_kwargs)
  File "/usr/lib/python3.9/site-packages/requests/sessions.py", line 655, in send
    r = adapter.send(request, **kwargs)
  File "/usr/lib/python3.9/site-packages/requests/adapters.py", line 516, in send
    raise ConnectionError(e, request=request)
requests.exceptions.ConnectionError: HTTPConnectionPool(host='tiny.cc', port=80): Max retries exceeded with url: /variety-options-063 (Caused by NewConnectionError('<urllib3.connection.HTTPConnection object at 0x7f8af26b9700>: Failed to establish a new connection: [Errno -2] Name or service not known'))

(variety:2835): Gtk-WARNING **: 08:40:18.880: Failed to measure available space: The specified location is not supported
TagLib: MPEG::Header::parse() -- MPEG header did not match MPEG synch.
TagLib: MPEG::Header::parse() -- MPEG header did not match MPEG synch.
TagLib: MPEG::Header::parse() -- MPEG header did not match MPEG synch.
GPL Ghostscript 9.54.0: Unrecoverable error, exit code 1
GPL Ghostscript 9.54.0: Unrecoverable error, exit code 1
GPL Ghostscript 9.54.0: Unrecoverable error, exit code 1
GPL Ghostscript 9.54.0: Unrecoverable error, exit code 1
GPL Ghostscript 9.54.0: Unrecoverable error, exit code 1
GPL Ghostscript 9.54.0: Unrecoverable error, exit code 1
GPL Ghostscript 9.54.0: Unrecoverable error, exit code 1
GPL Ghostscript 9.54.0: Unrecoverable error, exit code 1
GPL Ghostscript 9.54.0: Unrecoverable error, exit code 1
GPL Ghostscript 9.54.0: Unrecoverable error, exit code 1
GPL Ghostscript 9.54.0: Unrecoverable error, exit code 1
GPL Ghostscript 9.54.0: Unrecoverable error, exit code 1
GPL Ghostscript 9.54.0: Unrecoverable error, exit code 1
GPL Ghostscript 9.54.0: Unrecoverable error, exit code 1
GPL Ghostscript 9.54.0: Unrecoverable error, exit code 1
GPL Ghostscript 9.54.0: Unrecoverable error, exit code 1
GPL Ghostscript 9.54.0: Unrecoverable error, exit code 1
GPL Ghostscript 9.54.0: Unrecoverable error, exit code 1
GPL Ghostscript 9.54.0: Unrecoverable error, exit code 1
GPL Ghostscript 9.54.0: Unrecoverable error, exit code 1
GPL Ghostscript 9.54.0: Unrecoverable error, exit code 1
GPL Ghostscript 9.54.0: Unrecoverable error, exit code 1
GPL Ghostscript 9.54.0: Unrecoverable error, exit code 1
GPL Ghostscript 9.54.0: Unrecoverable error, exit code 1
GPL Ghostscript 9.54.0: Unrecoverable error, exit code 1
GPL Ghostscript 9.54.0: Unrecoverable error, exit code 1
GPL Ghostscript 9.54.0: Unrecoverable error, exit code 1
GPL Ghostscript 9.54.0: Unrecoverable error, exit code 1
GPL Ghostscript 9.54.0: Unrecoverable error, exit code 1
GPL Ghostscript 9.54.0: Unrecoverable error, exit code 1
GPL Ghostscript 9.54.0: Unrecoverable error, exit code 1
GPL Ghostscript 9.54.0: Unrecoverable error, exit code 1
GPL Ghostscript 9.54.0: Unrecoverable error, exit code 1
GPL Ghostscript 9.54.0: Unrecoverable error, exit code 1
GPL Ghostscript 9.54.0: Unrecoverable error, exit code 1
ERROR: 2021-04-27 08:40:22,841: server_options_thread() 'Could not fetch Variety serverside options'
Traceback (most recent call last):
  File "/usr/lib/python3.9/site-packages/urllib3/connection.py", line 169, in _new_conn
    conn = connection.create_connection(
  File "/usr/lib/python3.9/site-packages/urllib3/util/connection.py", line 73, in create_connection
    for res in socket.getaddrinfo(host, port, family, socket.SOCK_STREAM):
  File "/usr/lib/python3.9/socket.py", line 953, in getaddrinfo
    for res in _socket.getaddrinfo(host, port, family, type, proto, flags):
socket.gaierror: [Errno -2] Name or service not known

During handling of the above exception, another exception occurred:

Traceback (most recent call last):
  File "/usr/lib/python3.9/site-packages/urllib3/connectionpool.py", line 699, in urlopen
    httplib_response = self._make_request(
  File "/usr/lib/python3.9/site-packages/urllib3/connectionpool.py", line 394, in _make_request
    conn.request(method, url, **httplib_request_kw)
  File "/usr/lib/python3.9/site-packages/urllib3/connection.py", line 234, in request
    super(HTTPConnection, self).request(method, url, body=body, headers=headers)
  File "/usr/lib/python3.9/http/client.py", line 1253, in request
    self._send_request(method, url, body, headers, encode_chunked)
  File "/usr/lib/python3.9/http/client.py", line 1299, in _send_request
    self.endheaders(body, encode_chunked=encode_chunked)
  File "/usr/lib/python3.9/http/client.py", line 1248, in endheaders
    self._send_output(message_body, encode_chunked=encode_chunked)
  File "/usr/lib/python3.9/http/client.py", line 1008, in _send_output
    self.send(msg)
  File "/usr/lib/python3.9/http/client.py", line 948, in send
    self.connect()
  File "/usr/lib/python3.9/site-packages/urllib3/connection.py", line 200, in connect
    conn = self._new_conn()
  File "/usr/lib/python3.9/site-packages/urllib3/connection.py", line 181, in _new_conn
    raise NewConnectionError(
urllib3.exceptions.NewConnectionError: <urllib3.connection.HTTPConnection object at 0x7f8af26b97c0>: Failed to establish a new connection: [Errno -2] Name or service not known

During handling of the above exception, another exception occurred:

Traceback (most recent call last):
  File "/usr/lib/python3.9/site-packages/requests/adapters.py", line 439, in send
    resp = conn.urlopen(
  File "/usr/lib/python3.9/site-packages/urllib3/connectionpool.py", line 755, in urlopen
    retries = retries.increment(
  File "/usr/lib/python3.9/site-packages/urllib3/util/retry.py", line 574, in increment
    raise MaxRetryError(_pool, url, error or ResponseError(cause))
urllib3.exceptions.MaxRetryError: HTTPConnectionPool(host='tiny.cc', port=80): Max retries exceeded with url: /variety-options-063 (Caused by NewConnectionError('<urllib3.connection.HTTPConnection object at 0x7f8af26b97c0>: Failed to establish a new connection: [Errno -2] Name or service not known'))

During handling of the above exception, another exception occurred:

Traceback (most recent call last):
  File "/usr/lib/python3.9/site-packages/variety/VarietyWindow.py", line 1086, in server_options_thread
    self.server_options = Util.fetch_json(VarietyWindow.SERVERSIDE_OPTIONS_URL)
  File "/usr/lib/python3.9/site-packages/variety/Util.py", line 644, in fetch_json
    return Util.request(url, data, **request_kwargs).json()
  File "/usr/lib/python3.9/site-packages/variety/Util.py", line 614, in request
    r = requests.request(
  File "/usr/lib/python3.9/site-packages/requests/api.py", line 61, in request
    return session.request(method=method, url=url, **kwargs)
  File "/usr/lib/python3.9/site-packages/requests/sessions.py", line 542, in request
    resp = self.send(prep, **send_kwargs)
  File "/usr/lib/python3.9/site-packages/requests/sessions.py", line 655, in send
    r = adapter.send(request, **kwargs)
  File "/usr/lib/python3.9/site-packages/requests/adapters.py", line 516, in send
    raise ConnectionError(e, request=request)
requests.exceptions.ConnectionError: HTTPConnectionPool(host='tiny.cc', port=80): Max retries exceeded with url: /variety-options-063 (Caused by NewConnectionError('<urllib3.connection.HTTPConnection object at 0x7f8af26b97c0>: Failed to establish a new connection: [Errno -2] Name or service not known'))
kdeinit5: PID 5692 terminated.
ERROR: 2021-04-27 08:40:52,872: server_options_thread() 'Could not fetch Variety serverside options'
Traceback (most recent call last):
  File "/usr/lib/python3.9/site-packages/urllib3/connection.py", line 169, in _new_conn
    conn = connection.create_connection(
  File "/usr/lib/python3.9/site-packages/urllib3/util/connection.py", line 73, in create_connection
    for res in socket.getaddrinfo(host, port, family, socket.SOCK_STREAM):
  File "/usr/lib/python3.9/socket.py", line 953, in getaddrinfo
    for res in _socket.getaddrinfo(host, port, family, type, proto, flags):
socket.gaierror: [Errno -2] Name or service not known

During handling of the above exception, another exception occurred:

Traceback (most recent call last):
  File "/usr/lib/python3.9/site-packages/urllib3/connectionpool.py", line 699, in urlopen
    httplib_response = self._make_request(
  File "/usr/lib/python3.9/site-packages/urllib3/connectionpool.py", line 394, in _make_request
    conn.request(method, url, **httplib_request_kw)
  File "/usr/lib/python3.9/site-packages/urllib3/connection.py", line 234, in request
    super(HTTPConnection, self).request(method, url, body=body, headers=headers)
  File "/usr/lib/python3.9/http/client.py", line 1253, in request
    self._send_request(method, url, body, headers, encode_chunked)
  File "/usr/lib/python3.9/http/client.py", line 1299, in _send_request
    self.endheaders(body, encode_chunked=encode_chunked)
  File "/usr/lib/python3.9/http/client.py", line 1248, in endheaders
    self._send_output(message_body, encode_chunked=encode_chunked)
  File "/usr/lib/python3.9/http/client.py", line 1008, in _send_output
    self.send(msg)
  File "/usr/lib/python3.9/http/client.py", line 948, in send
    self.connect()
  File "/usr/lib/python3.9/site-packages/urllib3/connection.py", line 200, in connect
    conn = self._new_conn()
  File "/usr/lib/python3.9/site-packages/urllib3/connection.py", line 181, in _new_conn
    raise NewConnectionError(
urllib3.exceptions.NewConnectionError: <urllib3.connection.HTTPConnection object at 0x7f8b1c06aa90>: Failed to establish a new connection: [Errno -2] Name or service not known

During handling of the above exception, another exception occurred:

Traceback (most recent call last):
  File "/usr/lib/python3.9/site-packages/requests/adapters.py", line 439, in send
    resp = conn.urlopen(
  File "/usr/lib/python3.9/site-packages/urllib3/connectionpool.py", line 755, in urlopen
    retries = retries.increment(
  File "/usr/lib/python3.9/site-packages/urllib3/util/retry.py", line 574, in increment
    raise MaxRetryError(_pool, url, error or ResponseError(cause))
urllib3.exceptions.MaxRetryError: HTTPConnectionPool(host='tiny.cc', port=80): Max retries exceeded with url: /variety-options-063 (Caused by NewConnectionError('<urllib3.connection.HTTPConnection object at 0x7f8b1c06aa90>: Failed to establish a new connection: [Errno -2] Name or service not known'))

During handling of the above exception, another exception occurred:

Traceback (most recent call last):
  File "/usr/lib/python3.9/site-packages/variety/VarietyWindow.py", line 1086, in server_options_thread
    self.server_options = Util.fetch_json(VarietyWindow.SERVERSIDE_OPTIONS_URL)
  File "/usr/lib/python3.9/site-packages/variety/Util.py", line 644, in fetch_json
    return Util.request(url, data, **request_kwargs).json()
  File "/usr/lib/python3.9/site-packages/variety/Util.py", line 614, in request
    r = requests.request(
  File "/usr/lib/python3.9/site-packages/requests/api.py", line 61, in request
    return session.request(method=method, url=url, **kwargs)
  File "/usr/lib/python3.9/site-packages/requests/sessions.py", line 542, in request
    resp = self.send(prep, **send_kwargs)
  File "/usr/lib/python3.9/site-packages/requests/sessions.py", line 655, in send
    r = adapter.send(request, **kwargs)
  File "/usr/lib/python3.9/site-packages/requests/adapters.py", line 516, in send
    raise ConnectionError(e, request=request)
requests.exceptions.ConnectionError: HTTPConnectionPool(host='tiny.cc', port=80): Max retries exceeded with url: /variety-options-063 (Caused by NewConnectionError('<urllib3.connection.HTTPConnection object at 0x7f8b1c06aa90>: Failed to establish a new connection: [Errno -2] Name or service not known'))
TagLib: MPEG::Header::parse() -- MPEG header did not match MPEG synch.
TagLib: MPEG::Header::parse() -- MPEG header did not match MPEG synch.
TagLib: MPEG::Header::parse() -- MPEG header did not match MPEG synch.
GPL Ghostscript 9.54.0: Unrecoverable error, exit code 1
GPL Ghostscript 9.54.0: Unrecoverable error, exit code 1
GPL Ghostscript 9.54.0: Unrecoverable error, exit code 1
GPL Ghostscript 9.54.0: Unrecoverable error, exit code 1
GPL Ghostscript 9.54.0: Unrecoverable error, exit code 1
GPL Ghostscript 9.54.0: Unrecoverable error, exit code 1
GPL Ghostscript 9.54.0: Unrecoverable error, exit code 1
GPL Ghostscript 9.54.0: Unrecoverable error, exit code 1
GPL Ghostscript 9.54.0: Unrecoverable error, exit code 1
GPL Ghostscript 9.54.0: Unrecoverable error, exit code 1
GPL Ghostscript 9.54.0: Unrecoverable error, exit code 1
GPL Ghostscript 9.54.0: Unrecoverable error, exit code 1
GPL Ghostscript 9.54.0: Unrecoverable error, exit code 1
GPL Ghostscript 9.54.0: Unrecoverable error, exit code 1
GPL Ghostscript 9.54.0: Unrecoverable error, exit code 1
GPL Ghostscript 9.54.0: Unrecoverable error, exit code 1
GPL Ghostscript 9.54.0: Unrecoverable error, exit code 1
GPL Ghostscript 9.54.0: Unrecoverable error, exit code 1
GPL Ghostscript 9.54.0: Unrecoverable error, exit code 1
GPL Ghostscript 9.54.0: Unrecoverable error, exit code 1
GPL Ghostscript 9.54.0: Unrecoverable error, exit code 1
GPL Ghostscript 9.54.0: Unrecoverable error, exit code 1
GPL Ghostscript 9.54.0: Unrecoverable error, exit code 1
GPL Ghostscript 9.54.0: Unrecoverable error, exit code 1
GPL Ghostscript 9.54.0: Unrecoverable error, exit code 1
GPL Ghostscript 9.54.0: Unrecoverable error, exit code 1
GPL Ghostscript 9.54.0: Unrecoverable error, exit code 1
GPL Ghostscript 9.54.0: Unrecoverable error, exit code 1
GPL Ghostscript 9.54.0: Unrecoverable error, exit code 1
GPL Ghostscript 9.54.0: Unrecoverable error, exit code 1
GPL Ghostscript 9.54.0: Unrecoverable error, exit code 1
GPL Ghostscript 9.54.0: Unrecoverable error, exit code 1
GPL Ghostscript 9.54.0: Unrecoverable error, exit code 1
GPL Ghostscript 9.54.0: Unrecoverable error, exit code 1
GPL Ghostscript 9.54.0: Unrecoverable error, exit code 1
kdeinit5: Got EXEC_NEW '/usr/lib/qt/plugins/kf5/kio/baloosearch.so' from launcher.
kdeinit5: preparing to launch '/usr/lib/qt/plugins/kf5/kio/baloosearch.so'
kdeinit5: Got EXEC_NEW '/usr/lib/qt/plugins/kf5/kio/baloosearch.so' from launcher.
kdeinit5: preparing to launch '/usr/lib/qt/plugins/kf5/kio/baloosearch.so'
kdeinit5: Got EXEC_NEW '/usr/lib/qt/plugins/kf5/kio/baloosearch.so' from launcher.
kdeinit5: preparing to launch '/usr/lib/qt/plugins/kf5/kio/baloosearch.so'
kdeinit5: Got EXEC_NEW '/usr/lib/qt/plugins/kf5/kio/baloosearch.so' from launcher.
kdeinit5: preparing to launch '/usr/lib/qt/plugins/kf5/kio/baloosearch.so'
kdeinit5: Got EXEC_NEW '/usr/lib/qt/plugins/kf5/kio/baloosearch.so' from launcher.
kdeinit5: preparing to launch '/usr/lib/qt/plugins/kf5/kio/baloosearch.so'

(variety:2835): Gtk-WARNING **: 08:41:22.386: Failed to measure available space: The specified location is not supported

(variety:2835): Gtk-WARNING **: 08:41:22.416: Failed to measure available space: The specified location is not supported
GPL Ghostscript 9.54.0: Unrecoverable error, exit code 1
kdeinit5: PID 5688 terminated.
ERROR: 2021-04-27 08:41:51,698: download_one_from() 'Could not download wallpaper:'
Traceback (most recent call last):
  File "/usr/lib/python3.9/site-packages/urllib3/connection.py", line 169, in _new_conn
    conn = connection.create_connection(
  File "/usr/lib/python3.9/site-packages/urllib3/util/connection.py", line 73, in create_connection
    for res in socket.getaddrinfo(host, port, family, socket.SOCK_STREAM):
  File "/usr/lib/python3.9/socket.py", line 953, in getaddrinfo
    for res in _socket.getaddrinfo(host, port, family, type, proto, flags):
socket.gaierror: [Errno -2] Name or service not known

During handling of the above exception, another exception occurred:

Traceback (most recent call last):
  File "/usr/lib/python3.9/site-packages/urllib3/connectionpool.py", line 699, in urlopen
    httplib_response = self._make_request(
  File "/usr/lib/python3.9/site-packages/urllib3/connectionpool.py", line 382, in _make_request
    self._validate_conn(conn)
  File "/usr/lib/python3.9/site-packages/urllib3/connectionpool.py", line 1010, in _validate_conn
    conn.connect()
  File "/usr/lib/python3.9/site-packages/urllib3/connection.py", line 353, in connect
    conn = self._new_conn()
  File "/usr/lib/python3.9/site-packages/urllib3/connection.py", line 181, in _new_conn
    raise NewConnectionError(
urllib3.exceptions.NewConnectionError: <urllib3.connection.HTTPSConnection object at 0x7f8b1c06a850>: Failed to establish a new connection: [Errno -2] Name or service not known

During handling of the above exception, another exception occurred:

Traceback (most recent call last):
  File "/usr/lib/python3.9/site-packages/requests/adapters.py", line 439, in send
    resp = conn.urlopen(
  File "/usr/lib/python3.9/site-packages/urllib3/connectionpool.py", line 755, in urlopen
    retries = retries.increment(
  File "/usr/lib/python3.9/site-packages/urllib3/util/retry.py", line 574, in increment
    raise MaxRetryError(_pool, url, error or ResponseError(cause))
urllib3.exceptions.MaxRetryError: HTTPSConnectionPool(host='www.bing.com', port=443): Max retries exceeded with url: /HPImageArchive.aspx?format=js&idx=0&n=100&mkt=en-US (Caused by NewConnectionError('<urllib3.connection.HTTPSConnection object at 0x7f8b1c06a850>: Failed to establish a new connection: [Errno -2] Name or service not known'))

During handling of the above exception, another exception occurred:

Traceback (most recent call last):
  File "/usr/lib/python3.9/site-packages/variety/VarietyWindow.py", line 1160, in download_one_from
    file = downloader.download_one()
  File "/usr/lib/python3.9/site-packages/variety/plugins/downloaders/DefaultDownloader.py", line 141, in download_one
    items = self.fill_queue()
  File "/usr/lib/python3.9/site-packages/variety/plugins/builtin/downloaders/BingDownloader.py", line 61, in fill_queue
    s = Util.fetch_json(BingDownloader.BING_JSON_URL)
  File "/usr/lib/python3.9/site-packages/variety/Util.py", line 644, in fetch_json
    return Util.request(url, data, **request_kwargs).json()
  File "/usr/lib/python3.9/site-packages/variety/Util.py", line 614, in request
    r = requests.request(
  File "/usr/lib/python3.9/site-packages/requests/api.py", line 61, in request
    return session.request(method=method, url=url, **kwargs)
  File "/usr/lib/python3.9/site-packages/requests/sessions.py", line 542, in request
    resp = self.send(prep, **send_kwargs)
  File "/usr/lib/python3.9/site-packages/requests/sessions.py", line 655, in send
    r = adapter.send(request, **kwargs)
  File "/usr/lib/python3.9/site-packages/requests/adapters.py", line 516, in send
    raise ConnectionError(e, request=request)
requests.exceptions.ConnectionError: HTTPSConnectionPool(host='www.bing.com', port=443): Max retries exceeded with url: /HPImageArchive.aspx?format=js&idx=0&n=100&mkt=en-US (Caused by NewConnectionError('<urllib3.connection.HTTPSConnection object at 0x7f8b1c06a850>: Failed to establish a new connection: [Errno -2] Name or service not known'))
ERROR: 2021-04-27 08:41:53,703: download_one_from() 'Could not download wallpaper:'
Traceback (most recent call last):
  File "/usr/lib/python3.9/site-packages/urllib3/connection.py", line 169, in _new_conn
    conn = connection.create_connection(
  File "/usr/lib/python3.9/site-packages/urllib3/util/connection.py", line 73, in create_connection
    for res in socket.getaddrinfo(host, port, family, socket.SOCK_STREAM):
  File "/usr/lib/python3.9/socket.py", line 953, in getaddrinfo
    for res in _socket.getaddrinfo(host, port, family, type, proto, flags):
socket.gaierror: [Errno -2] Name or service not known

During handling of the above exception, another exception occurred:

Traceback (most recent call last):
  File "/usr/lib/python3.9/site-packages/urllib3/connectionpool.py", line 699, in urlopen
    httplib_response = self._make_request(
  File "/usr/lib/python3.9/site-packages/urllib3/connectionpool.py", line 394, in _make_request
    conn.request(method, url, **httplib_request_kw)
  File "/usr/lib/python3.9/site-packages/urllib3/connection.py", line 234, in request
    super(HTTPConnection, self).request(method, url, body=body, headers=headers)
  File "/usr/lib/python3.9/http/client.py", line 1253, in request
    self._send_request(method, url, body, headers, encode_chunked)
  File "/usr/lib/python3.9/http/client.py", line 1299, in _send_request
    self.endheaders(body, encode_chunked=encode_chunked)
  File "/usr/lib/python3.9/http/client.py", line 1248, in endheaders
    self._send_output(message_body, encode_chunked=encode_chunked)
  File "/usr/lib/python3.9/http/client.py", line 1008, in _send_output
    self.send(msg)
  File "/usr/lib/python3.9/http/client.py", line 948, in send
    self.connect()
  File "/usr/lib/python3.9/site-packages/urllib3/connection.py", line 200, in connect
    conn = self._new_conn()
  File "/usr/lib/python3.9/site-packages/urllib3/connection.py", line 181, in _new_conn
    raise NewConnectionError(
urllib3.exceptions.NewConnectionError: <urllib3.connection.HTTPConnection object at 0x7f8af26b9940>: Failed to establish a new connection: [Errno -2] Name or service not known

During handling of the above exception, another exception occurred:

Traceback (most recent call last):
  File "/usr/lib/python3.9/site-packages/requests/adapters.py", line 439, in send
    resp = conn.urlopen(
  File "/usr/lib/python3.9/site-packages/urllib3/connectionpool.py", line 755, in urlopen
    retries = retries.increment(
  File "/usr/lib/python3.9/site-packages/urllib3/util/retry.py", line 574, in increment
    raise MaxRetryError(_pool, url, error or ResponseError(cause))
urllib3.exceptions.MaxRetryError: HTTPConnectionPool(host='apod.nasa.gov', port=80): Max retries exceeded with url: /apod/archivepix.html (Caused by NewConnectionError('<urllib3.connection.HTTPConnection object at 0x7f8af26b9940>: Failed to establish a new connection: [Errno -2] Name or service not known'))

During handling of the above exception, another exception occurred:

Traceback (most recent call last):
  File "/usr/lib/python3.9/site-packages/variety/VarietyWindow.py", line 1160, in download_one_from
    file = downloader.download_one()
  File "/usr/lib/python3.9/site-packages/variety/plugins/downloaders/DefaultDownloader.py", line 141, in download_one
    items = self.fill_queue()
  File "/usr/lib/python3.9/site-packages/variety/plugins/builtin/downloaders/APODDownloader.py", line 59, in fill_queue
    s = Util.html_soup(self.ROOT_URL + "archivepix.html")
  File "/usr/lib/python3.9/site-packages/variety/Util.py", line 648, in html_soup
    return bs4.BeautifulSoup(Util.fetch(url, data, **request_kwargs), "lxml")
  File "/usr/lib/python3.9/site-packages/variety/Util.py", line 636, in fetch
    return Util.request(url, data, **request_kwargs).text
  File "/usr/lib/python3.9/site-packages/variety/Util.py", line 614, in request
    r = requests.request(
  File "/usr/lib/python3.9/site-packages/requests/api.py", line 61, in request
    return session.request(method=method, url=url, **kwargs)
  File "/usr/lib/python3.9/site-packages/requests/sessions.py", line 542, in request
    resp = self.send(prep, **send_kwargs)
  File "/usr/lib/python3.9/site-packages/requests/sessions.py", line 655, in send
    r = adapter.send(request, **kwargs)
  File "/usr/lib/python3.9/site-packages/requests/adapters.py", line 516, in send
    raise ConnectionError(e, request=request)
requests.exceptions.ConnectionError: HTTPConnectionPool(host='apod.nasa.gov', port=80): Max retries exceeded with url: /apod/archivepix.html (Caused by NewConnectionError('<urllib3.connection.HTTPConnection object at 0x7f8af26b9940>: Failed to establish a new connection: [Errno -2] Name or service not known'))
ERROR: 2021-04-27 08:41:54,707: download_one_from() 'Could not download wallpaper:'
Traceback (most recent call last):
  File "/usr/lib/python3.9/site-packages/urllib3/connection.py", line 169, in _new_conn
    conn = connection.create_connection(
  File "/usr/lib/python3.9/site-packages/urllib3/util/connection.py", line 73, in create_connection
    for res in socket.getaddrinfo(host, port, family, socket.SOCK_STREAM):
  File "/usr/lib/python3.9/socket.py", line 953, in getaddrinfo
    for res in _socket.getaddrinfo(host, port, family, type, proto, flags):
socket.gaierror: [Errno -2] Name or service not known

During handling of the above exception, another exception occurred:

Traceback (most recent call last):
  File "/usr/lib/python3.9/site-packages/urllib3/connectionpool.py", line 699, in urlopen
    httplib_response = self._make_request(
  File "/usr/lib/python3.9/site-packages/urllib3/connectionpool.py", line 382, in _make_request
    self._validate_conn(conn)
  File "/usr/lib/python3.9/site-packages/urllib3/connectionpool.py", line 1010, in _validate_conn
    conn.connect()
  File "/usr/lib/python3.9/site-packages/urllib3/connection.py", line 353, in connect
    conn = self._new_conn()
  File "/usr/lib/python3.9/site-packages/urllib3/connection.py", line 181, in _new_conn
    raise NewConnectionError(
urllib3.exceptions.NewConnectionError: <urllib3.connection.HTTPSConnection object at 0x7f8af26b9d60>: Failed to establish a new connection: [Errno -2] Name or service not known

During handling of the above exception, another exception occurred:

Traceback (most recent call last):
  File "/usr/lib/python3.9/site-packages/requests/adapters.py", line 439, in send
    resp = conn.urlopen(
  File "/usr/lib/python3.9/site-packages/urllib3/connectionpool.py", line 755, in urlopen
    retries = retries.increment(
  File "/usr/lib/python3.9/site-packages/urllib3/util/retry.py", line 574, in increment
    raise MaxRetryError(_pool, url, error or ResponseError(cause))
urllib3.exceptions.MaxRetryError: HTTPSConnectionPool(host='api.flickr.com', port=443): Max retries exceeded with url: /services/rest/?method=flickr.photos.search&api_key=0553a848c09bcfd21d3a984d9408c04e&per_page=500&tag_mode=all&format=json&nojsoncallback=1&user_id=93647178@N00 (Caused by NewConnectionError('<urllib3.connection.HTTPSConnection object at 0x7f8af26b9d60>: Failed to establish a new connection: [Errno -2] Name or service not known'))

During handling of the above exception, another exception occurred:

Traceback (most recent call last):
  File "/usr/lib/python3.9/site-packages/variety/VarietyWindow.py", line 1160, in download_one_from
    file = downloader.download_one()
  File "/usr/lib/python3.9/site-packages/variety/plugins/downloaders/DefaultDownloader.py", line 141, in download_one
    items = self.fill_queue()
  File "/usr/lib/python3.9/site-packages/variety/FlickrDownloader.py", line 161, in fill_queue
    resp = FlickrDownloader.fetch(call)
  File "/usr/lib/python3.9/site-packages/variety/FlickrDownloader.py", line 74, in fetch
    return Util.fetch_json(call)
  File "/usr/lib/python3.9/site-packages/variety/Util.py", line 644, in fetch_json
    return Util.request(url, data, **request_kwargs).json()
  File "/usr/lib/python3.9/site-packages/variety/Util.py", line 614, in request
    r = requests.request(
  File "/usr/lib/python3.9/site-packages/requests/api.py", line 61, in request
    return session.request(method=method, url=url, **kwargs)
  File "/usr/lib/python3.9/site-packages/requests/sessions.py", line 542, in request
    resp = self.send(prep, **send_kwargs)
  File "/usr/lib/python3.9/site-packages/requests/sessions.py", line 655, in send
    r = adapter.send(request, **kwargs)
  File "/usr/lib/python3.9/site-packages/requests/adapters.py", line 516, in send
    raise ConnectionError(e, request=request)
requests.exceptions.ConnectionError: HTTPSConnectionPool(host='api.flickr.com', port=443): Max retries exceeded with url: /services/rest/?method=flickr.photos.search&api_key=0553a848c09bcfd21d3a984d9408c04e&per_page=500&tag_mode=all&format=json&nojsoncallback=1&user_id=93647178@N00 (Caused by NewConnectionError('<urllib3.connection.HTTPSConnection object at 0x7f8af26b9d60>: Failed to establish a new connection: [Errno -2] Name or service not known'))
ERROR: 2021-04-27 08:41:55,712: download_one_from() 'Could not download wallpaper:'
Traceback (most recent call last):
  File "/usr/lib/python3.9/site-packages/urllib3/connection.py", line 169, in _new_conn
    conn = connection.create_connection(
  File "/usr/lib/python3.9/site-packages/urllib3/util/connection.py", line 73, in create_connection
    for res in socket.getaddrinfo(host, port, family, socket.SOCK_STREAM):
  File "/usr/lib/python3.9/socket.py", line 953, in getaddrinfo
    for res in _socket.getaddrinfo(host, port, family, type, proto, flags):
socket.gaierror: [Errno -2] Name or service not known

During handling of the above exception, another exception occurred:

Traceback (most recent call last):
  File "/usr/lib/python3.9/site-packages/urllib3/connectionpool.py", line 699, in urlopen
    httplib_response = self._make_request(
  File "/usr/lib/python3.9/site-packages/urllib3/connectionpool.py", line 382, in _make_request
    self._validate_conn(conn)
  File "/usr/lib/python3.9/site-packages/urllib3/connectionpool.py", line 1010, in _validate_conn
    conn.connect()
  File "/usr/lib/python3.9/site-packages/urllib3/connection.py", line 353, in connect
    conn = self._new_conn()
  File "/usr/lib/python3.9/site-packages/urllib3/connection.py", line 181, in _new_conn
    raise NewConnectionError(
urllib3.exceptions.NewConnectionError: <urllib3.connection.HTTPSConnection object at 0x7f8b1c08de50>: Failed to establish a new connection: [Errno -2] Name or service not known

During handling of the above exception, another exception occurred:

Traceback (most recent call last):
  File "/usr/lib/python3.9/site-packages/requests/adapters.py", line 439, in send
    resp = conn.urlopen(
  File "/usr/lib/python3.9/site-packages/urllib3/connectionpool.py", line 755, in urlopen
    retries = retries.increment(
  File "/usr/lib/python3.9/site-packages/urllib3/util/retry.py", line 574, in increment
    raise MaxRetryError(_pool, url, error or ResponseError(cause))
urllib3.exceptions.MaxRetryError: HTTPSConnectionPool(host='raw.githubusercontent.com', port=443): Max retries exceeded with url: /limhenry/earthview/3cd868a932cd652c4373c0f6ea8618a96b08be4e/wallpaper%20changer/data.json (Caused by NewConnectionError('<urllib3.connection.HTTPSConnection object at 0x7f8b1c08de50>: Failed to establish a new connection: [Errno -2] Name or service not known'))

During handling of the above exception, another exception occurred:

Traceback (most recent call last):
  File "/usr/lib/python3.9/site-packages/variety/VarietyWindow.py", line 1160, in download_one_from
    file = downloader.download_one()
  File "/usr/lib/python3.9/site-packages/variety/plugins/downloaders/DefaultDownloader.py", line 141, in download_one
    items = self.fill_queue()
  File "/usr/lib/python3.9/site-packages/variety/plugins/builtin/downloaders/EarthviewDownloader.py", line 57, in fill_queue
    queue = Util.fetch_json(DATA_URL)
  File "/usr/lib/python3.9/site-packages/variety/Util.py", line 644, in fetch_json
    return Util.request(url, data, **request_kwargs).json()
  File "/usr/lib/python3.9/site-packages/variety/Util.py", line 614, in request
    r = requests.request(
  File "/usr/lib/python3.9/site-packages/requests/api.py", line 61, in request
    return session.request(method=method, url=url, **kwargs)
  File "/usr/lib/python3.9/site-packages/requests/sessions.py", line 542, in request
    resp = self.send(prep, **send_kwargs)
  File "/usr/lib/python3.9/site-packages/requests/sessions.py", line 655, in send
    r = adapter.send(request, **kwargs)
  File "/usr/lib/python3.9/site-packages/requests/adapters.py", line 516, in send
    raise ConnectionError(e, request=request)
requests.exceptions.ConnectionError: HTTPSConnectionPool(host='raw.githubusercontent.com', port=443): Max retries exceeded with url: /limhenry/earthview/3cd868a932cd652c4373c0f6ea8618a96b08be4e/wallpaper%20changer/data.json (Caused by NewConnectionError('<urllib3.connection.HTTPSConnection object at 0x7f8b1c08de50>: Failed to establish a new connection: [Errno -2] Name or service not known'))
kdeinit5: Got EXEC_NEW '/usr/lib/qt/plugins/kf5/kio/tags.so' from launcher.
kdeinit5: preparing to launch '/usr/lib/qt/plugins/kf5/kio/tags.so'
kdeinit5: Got EXEC_NEW '/usr/lib/qt/plugins/kf5/kio/file.so' from launcher.
kdeinit5: preparing to launch '/usr/lib/qt/plugins/kf5/kio/file.so'
kdeinit5: Got EXEC_NEW '/usr/lib/qt/plugins/kf5/kio/file.so' from launcher.
kdeinit5: preparing to launch '/usr/lib/qt/plugins/kf5/kio/file.so'
kdeinit5: Got EXEC_NEW '/usr/lib/qt/plugins/kf5/kio/file.so' from launcher.
kdeinit5: preparing to launch '/usr/lib/qt/plugins/kf5/kio/file.so'
kdeinit5: Got EXEC_NEW '/usr/lib/qt/plugins/kf5/kio/file.so' from launcher.
kdeinit5: preparing to launch '/usr/lib/qt/plugins/kf5/kio/file.so'
kdeinit5: Got EXEC_NEW '/usr/lib/qt/plugins/kf5/kio/file.so' from launcher.
kdeinit5: preparing to launch '/usr/lib/qt/plugins/kf5/kio/file.so'
kdeinit5: Got EXEC_NEW '/usr/lib/qt/plugins/kf5/kio/thumbnail.so' from launcher.
kdeinit5: preparing to launch '/usr/lib/qt/plugins/kf5/kio/thumbnail.so'
kdeinit5: PID 5693 terminated.
kdeinit5: PID 5687 terminated.
kdeinit5: PID 10535 terminated.
kdeinit5: PID 10534 terminated.
kdeinit5: PID 10539 terminated.
kdeinit5: PID 10531 terminated.
kdeinit5: PID 10538 terminated.
kdeinit5: PID 10532 terminated.
kdeinit5: PID 10540 terminated.
kdeinit5: Got EXEC_NEW '/usr/lib/qt/plugins/kf5/kio/file.so' from launcher.
kdeinit5: preparing to launch '/usr/lib/qt/plugins/kf5/kio/file.so'
kdeinit5: Got EXEC_NEW '/usr/lib/qt/plugins/kf5/kio/file.so' from launcher.
kdeinit5: preparing to launch '/usr/lib/qt/plugins/kf5/kio/file.so'
[ALSOFT] (EE) Failed to set real-time priority for thread: Operation not permitted (1)
[ALSOFT] (EE) Failed to set real-time priority for thread: Operation not permitted (1)
[ALSOFT] (EE) Failed to set real-time priority for thread: Operation not permitted (1)
kdeinit5: PID 10551 terminated.
kdeinit5: PID 3184 terminated.
kdeinit5: PID 3156 terminated.
kdeinit5: Got EXEC_NEW '/usr/lib/qt/plugins/kf5/kio/file.so' from launcher.
kdeinit5: preparing to launch '/usr/lib/qt/plugins/kf5/kio/file.so'
kdeinit5: PID 8671 terminated.
kdeinit5: PID 8673 terminated.
kdeinit5: PID 8672 terminated.
kdeinit5: PID 10552 terminated.
kdeinit5: PID 5686 terminated.
kdeinit5: PID 5691 terminated.
kdeinit5: PID 8669 terminated.
kdeinit5: PID 10617 terminated.
kdeinit5: PID 8670 terminated.
kdeinit5: PID 5694 terminated.

(pamac-manager:11424): Gtk-WARNING **: 08:43:33.433: Theme parsing error: gtk-dark.css:6342:10: 'height' is not a valid property name

(pamac-manager:11424): Gdk-CRITICAL **: 08:43:34.129: gdk_window_set_cursor: assertion 'GDK_IS_WINDOW (window)' failed
ERROR: 2021-04-27 08:43:34,749: download_one_from() 'Could not download wallpaper:'
Traceback (most recent call last):
  File "/usr/lib/python3.9/site-packages/urllib3/connection.py", line 169, in _new_conn
    conn = connection.create_connection(
  File "/usr/lib/python3.9/site-packages/urllib3/util/connection.py", line 73, in create_connection
    for res in socket.getaddrinfo(host, port, family, socket.SOCK_STREAM):
  File "/usr/lib/python3.9/socket.py", line 953, in getaddrinfo
    for res in _socket.getaddrinfo(host, port, family, type, proto, flags):
socket.gaierror: [Errno -2] Name or service not known

During handling of the above exception, another exception occurred:

Traceback (most recent call last):
  File "/usr/lib/python3.9/site-packages/urllib3/connectionpool.py", line 699, in urlopen
    httplib_response = self._make_request(
  File "/usr/lib/python3.9/site-packages/urllib3/connectionpool.py", line 382, in _make_request
    self._validate_conn(conn)
  File "/usr/lib/python3.9/site-packages/urllib3/connectionpool.py", line 1010, in _validate_conn
    conn.connect()
  File "/usr/lib/python3.9/site-packages/urllib3/connection.py", line 353, in connect
    conn = self._new_conn()
  File "/usr/lib/python3.9/site-packages/urllib3/connection.py", line 181, in _new_conn
    raise NewConnectionError(
urllib3.exceptions.NewConnectionError: <urllib3.connection.HTTPSConnection object at 0x7f8b1c08db20>: Failed to establish a new connection: [Errno -2] Name or service not known

During handling of the above exception, another exception occurred:

Traceback (most recent call last):
  File "/usr/lib/python3.9/site-packages/requests/adapters.py", line 439, in send
    resp = conn.urlopen(
  File "/usr/lib/python3.9/site-packages/urllib3/connectionpool.py", line 755, in urlopen
    retries = retries.increment(
  File "/usr/lib/python3.9/site-packages/urllib3/util/retry.py", line 574, in increment
    raise MaxRetryError(_pool, url, error or ResponseError(cause))
urllib3.exceptions.MaxRetryError: HTTPSConnectionPool(host='www.bing.com', port=443): Max retries exceeded with url: /HPImageArchive.aspx?format=js&idx=0&n=100&mkt=en-US (Caused by NewConnectionError('<urllib3.connection.HTTPSConnection object at 0x7f8b1c08db20>: Failed to establish a new connection: [Errno -2] Name or service not known'))

During handling of the above exception, another exception occurred:

Traceback (most recent call last):
  File "/usr/lib/python3.9/site-packages/variety/VarietyWindow.py", line 1160, in download_one_from
    file = downloader.download_one()
  File "/usr/lib/python3.9/site-packages/variety/plugins/downloaders/DefaultDownloader.py", line 141, in download_one
    items = self.fill_queue()
  File "/usr/lib/python3.9/site-packages/variety/plugins/builtin/downloaders/BingDownloader.py", line 61, in fill_queue
    s = Util.fetch_json(BingDownloader.BING_JSON_URL)
  File "/usr/lib/python3.9/site-packages/variety/Util.py", line 644, in fetch_json
    return Util.request(url, data, **request_kwargs).json()
  File "/usr/lib/python3.9/site-packages/variety/Util.py", line 614, in request
    r = requests.request(
  File "/usr/lib/python3.9/site-packages/requests/api.py", line 61, in request
    return session.request(method=method, url=url, **kwargs)
  File "/usr/lib/python3.9/site-packages/requests/sessions.py", line 542, in request
    resp = self.send(prep, **send_kwargs)
  File "/usr/lib/python3.9/site-packages/requests/sessions.py", line 655, in send
    r = adapter.send(request, **kwargs)
  File "/usr/lib/python3.9/site-packages/requests/adapters.py", line 516, in send
    raise ConnectionError(e, request=request)
requests.exceptions.ConnectionError: HTTPSConnectionPool(host='www.bing.com', port=443): Max retries exceeded with url: /HPImageArchive.aspx?format=js&idx=0&n=100&mkt=en-US (Caused by NewConnectionError('<urllib3.connection.HTTPSConnection object at 0x7f8b1c08db20>: Failed to establish a new connection: [Errno -2] Name or service not known'))
ERROR: 2021-04-27 08:43:36,758: download_one_from() 'Could not download wallpaper:'
Traceback (most recent call last):
  File "/usr/lib/python3.9/site-packages/urllib3/connection.py", line 169, in _new_conn
    conn = connection.create_connection(
  File "/usr/lib/python3.9/site-packages/urllib3/util/connection.py", line 73, in create_connection
    for res in socket.getaddrinfo(host, port, family, socket.SOCK_STREAM):
  File "/usr/lib/python3.9/socket.py", line 953, in getaddrinfo
    for res in _socket.getaddrinfo(host, port, family, type, proto, flags):
socket.gaierror: [Errno -2] Name or service not known

During handling of the above exception, another exception occurred:

Traceback (most recent call last):
  File "/usr/lib/python3.9/site-packages/urllib3/connectionpool.py", line 699, in urlopen
    httplib_response = self._make_request(
  File "/usr/lib/python3.9/site-packages/urllib3/connectionpool.py", line 394, in _make_request
    conn.request(method, url, **httplib_request_kw)
  File "/usr/lib/python3.9/site-packages/urllib3/connection.py", line 234, in request
    super(HTTPConnection, self).request(method, url, body=body, headers=headers)
  File "/usr/lib/python3.9/http/client.py", line 1253, in request
    self._send_request(method, url, body, headers, encode_chunked)
  File "/usr/lib/python3.9/http/client.py", line 1299, in _send_request
    self.endheaders(body, encode_chunked=encode_chunked)
  File "/usr/lib/python3.9/http/client.py", line 1248, in endheaders
    self._send_output(message_body, encode_chunked=encode_chunked)
  File "/usr/lib/python3.9/http/client.py", line 1008, in _send_output
    self.send(msg)
  File "/usr/lib/python3.9/http/client.py", line 948, in send
    self.connect()
  File "/usr/lib/python3.9/site-packages/urllib3/connection.py", line 200, in connect
    conn = self._new_conn()
  File "/usr/lib/python3.9/site-packages/urllib3/connection.py", line 181, in _new_conn
    raise NewConnectionError(
urllib3.exceptions.NewConnectionError: <urllib3.connection.HTTPConnection object at 0x7f8af25e0e80>: Failed to establish a new connection: [Errno -2] Name or service not known

During handling of the above exception, another exception occurred:

Traceback (most recent call last):
  File "/usr/lib/python3.9/site-packages/requests/adapters.py", line 439, in send
    resp = conn.urlopen(
  File "/usr/lib/python3.9/site-packages/urllib3/connectionpool.py", line 755, in urlopen
    retries = retries.increment(
  File "/usr/lib/python3.9/site-packages/urllib3/util/retry.py", line 574, in increment
    raise MaxRetryError(_pool, url, error or ResponseError(cause))
urllib3.exceptions.MaxRetryError: HTTPConnectionPool(host='apod.nasa.gov', port=80): Max retries exceeded with url: /apod/archivepix.html (Caused by NewConnectionError('<urllib3.connection.HTTPConnection object at 0x7f8af25e0e80>: Failed to establish a new connection: [Errno -2] Name or service not known'))

During handling of the above exception, another exception occurred:

Traceback (most recent call last):
  File "/usr/lib/python3.9/site-packages/variety/VarietyWindow.py", line 1160, in download_one_from
    file = downloader.download_one()
  File "/usr/lib/python3.9/site-packages/variety/plugins/downloaders/DefaultDownloader.py", line 141, in download_one
    items = self.fill_queue()
  File "/usr/lib/python3.9/site-packages/variety/plugins/builtin/downloaders/APODDownloader.py", line 59, in fill_queue
    s = Util.html_soup(self.ROOT_URL + "archivepix.html")
  File "/usr/lib/python3.9/site-packages/variety/Util.py", line 648, in html_soup
    return bs4.BeautifulSoup(Util.fetch(url, data, **request_kwargs), "lxml")
  File "/usr/lib/python3.9/site-packages/variety/Util.py", line 636, in fetch
    return Util.request(url, data, **request_kwargs).text
  File "/usr/lib/python3.9/site-packages/variety/Util.py", line 614, in request
    r = requests.request(
  File "/usr/lib/python3.9/site-packages/requests/api.py", line 61, in request
    return session.request(method=method, url=url, **kwargs)
  File "/usr/lib/python3.9/site-packages/requests/sessions.py", line 542, in request
    resp = self.send(prep, **send_kwargs)
  File "/usr/lib/python3.9/site-packages/requests/sessions.py", line 655, in send
    r = adapter.send(request, **kwargs)
  File "/usr/lib/python3.9/site-packages/requests/adapters.py", line 516, in send
    raise ConnectionError(e, request=request)
requests.exceptions.ConnectionError: HTTPConnectionPool(host='apod.nasa.gov', port=80): Max retries exceeded with url: /apod/archivepix.html (Caused by NewConnectionError('<urllib3.connection.HTTPConnection object at 0x7f8af25e0e80>: Failed to establish a new connection: [Errno -2] Name or service not known'))
ERROR: 2021-04-27 08:43:37,762: download_one_from() 'Could not download wallpaper:'
Traceback (most recent call last):
  File "/usr/lib/python3.9/site-packages/urllib3/connection.py", line 169, in _new_conn
    conn = connection.create_connection(
  File "/usr/lib/python3.9/site-packages/urllib3/util/connection.py", line 73, in create_connection
    for res in socket.getaddrinfo(host, port, family, socket.SOCK_STREAM):
  File "/usr/lib/python3.9/socket.py", line 953, in getaddrinfo
    for res in _socket.getaddrinfo(host, port, family, type, proto, flags):
socket.gaierror: [Errno -2] Name or service not known

During handling of the above exception, another exception occurred:

Traceback (most recent call last):
  File "/usr/lib/python3.9/site-packages/urllib3/connectionpool.py", line 699, in urlopen
    httplib_response = self._make_request(
  File "/usr/lib/python3.9/site-packages/urllib3/connectionpool.py", line 382, in _make_request
    self._validate_conn(conn)
  File "/usr/lib/python3.9/site-packages/urllib3/connectionpool.py", line 1010, in _validate_conn
    conn.connect()
  File "/usr/lib/python3.9/site-packages/urllib3/connection.py", line 353, in connect
    conn = self._new_conn()
  File "/usr/lib/python3.9/site-packages/urllib3/connection.py", line 181, in _new_conn
    raise NewConnectionError(
urllib3.exceptions.NewConnectionError: <urllib3.connection.HTTPSConnection object at 0x7f8af26a54c0>: Failed to establish a new connection: [Errno -2] Name or service not known

During handling of the above exception, another exception occurred:

Traceback (most recent call last):
  File "/usr/lib/python3.9/site-packages/requests/adapters.py", line 439, in send
    resp = conn.urlopen(
  File "/usr/lib/python3.9/site-packages/urllib3/connectionpool.py", line 755, in urlopen
    retries = retries.increment(
  File "/usr/lib/python3.9/site-packages/urllib3/util/retry.py", line 574, in increment
    raise MaxRetryError(_pool, url, error or ResponseError(cause))
urllib3.exceptions.MaxRetryError: HTTPSConnectionPool(host='api.flickr.com', port=443): Max retries exceeded with url: /services/rest/?method=flickr.photos.search&api_key=0553a848c09bcfd21d3a984d9408c04e&per_page=500&tag_mode=all&format=json&nojsoncallback=1&user_id=93647178@N00 (Caused by NewConnectionError('<urllib3.connection.HTTPSConnection object at 0x7f8af26a54c0>: Failed to establish a new connection: [Errno -2] Name or service not known'))

During handling of the above exception, another exception occurred:

Traceback (most recent call last):
  File "/usr/lib/python3.9/site-packages/variety/VarietyWindow.py", line 1160, in download_one_from
    file = downloader.download_one()
  File "/usr/lib/python3.9/site-packages/variety/plugins/downloaders/DefaultDownloader.py", line 141, in download_one
    items = self.fill_queue()
  File "/usr/lib/python3.9/site-packages/variety/FlickrDownloader.py", line 161, in fill_queue
    resp = FlickrDownloader.fetch(call)
  File "/usr/lib/python3.9/site-packages/variety/FlickrDownloader.py", line 74, in fetch
    return Util.fetch_json(call)
  File "/usr/lib/python3.9/site-packages/variety/Util.py", line 644, in fetch_json
    return Util.request(url, data, **request_kwargs).json()
  File "/usr/lib/python3.9/site-packages/variety/Util.py", line 614, in request
    r = requests.request(
  File "/usr/lib/python3.9/site-packages/requests/api.py", line 61, in request
    return session.request(method=method, url=url, **kwargs)
  File "/usr/lib/python3.9/site-packages/requests/sessions.py", line 542, in request
    resp = self.send(prep, **send_kwargs)
  File "/usr/lib/python3.9/site-packages/requests/sessions.py", line 655, in send
    r = adapter.send(request, **kwargs)
  File "/usr/lib/python3.9/site-packages/requests/adapters.py", line 516, in send
    raise ConnectionError(e, request=request)
requests.exceptions.ConnectionError: HTTPSConnectionPool(host='api.flickr.com', port=443): Max retries exceeded with url: /services/rest/?method=flickr.photos.search&api_key=0553a848c09bcfd21d3a984d9408c04e&per_page=500&tag_mode=all&format=json&nojsoncallback=1&user_id=93647178@N00 (Caused by NewConnectionError('<urllib3.connection.HTTPSConnection object at 0x7f8af26a54c0>: Failed to establish a new connection: [Errno -2] Name or service not known'))
ERROR: 2021-04-27 08:43:38,783: download_one_from() 'Could not download wallpaper:'
Traceback (most recent call last):
  File "/usr/lib/python3.9/site-packages/urllib3/connection.py", line 169, in _new_conn
    conn = connection.create_connection(
  File "/usr/lib/python3.9/site-packages/urllib3/util/connection.py", line 73, in create_connection
    for res in socket.getaddrinfo(host, port, family, socket.SOCK_STREAM):
  File "/usr/lib/python3.9/socket.py", line 953, in getaddrinfo
    for res in _socket.getaddrinfo(host, port, family, type, proto, flags):
socket.gaierror: [Errno -2] Name or service not known

During handling of the above exception, another exception occurred:

Traceback (most recent call last):
  File "/usr/lib/python3.9/site-packages/urllib3/connectionpool.py", line 699, in urlopen
    httplib_response = self._make_request(
  File "/usr/lib/python3.9/site-packages/urllib3/connectionpool.py", line 382, in _make_request
    self._validate_conn(conn)
  File "/usr/lib/python3.9/site-packages/urllib3/connectionpool.py", line 1010, in _validate_conn
    conn.connect()
  File "/usr/lib/python3.9/site-packages/urllib3/connection.py", line 353, in connect
    conn = self._new_conn()
  File "/usr/lib/python3.9/site-packages/urllib3/connection.py", line 181, in _new_conn
    raise NewConnectionError(
urllib3.exceptions.NewConnectionError: <urllib3.connection.HTTPSConnection object at 0x7f8af26a5280>: Failed to establish a new connection: [Errno -2] Name or service not known

During handling of the above exception, another exception occurred:

Traceback (most recent call last):
  File "/usr/lib/python3.9/site-packages/requests/adapters.py", line 439, in send
    resp = conn.urlopen(
  File "/usr/lib/python3.9/site-packages/urllib3/connectionpool.py", line 755, in urlopen
    retries = retries.increment(
  File "/usr/lib/python3.9/site-packages/urllib3/util/retry.py", line 574, in increment
    raise MaxRetryError(_pool, url, error or ResponseError(cause))
urllib3.exceptions.MaxRetryError: HTTPSConnectionPool(host='raw.githubusercontent.com', port=443): Max retries exceeded with url: /limhenry/earthview/3cd868a932cd652c4373c0f6ea8618a96b08be4e/wallpaper%20changer/data.json (Caused by NewConnectionError('<urllib3.connection.HTTPSConnection object at 0x7f8af26a5280>: Failed to establish a new connection: [Errno -2] Name or service not known'))

During handling of the above exception, another exception occurred:

Traceback (most recent call last):
  File "/usr/lib/python3.9/site-packages/variety/VarietyWindow.py", line 1160, in download_one_from
    file = downloader.download_one()
  File "/usr/lib/python3.9/site-packages/variety/plugins/downloaders/DefaultDownloader.py", line 141, in download_one
    items = self.fill_queue()
  File "/usr/lib/python3.9/site-packages/variety/plugins/builtin/downloaders/EarthviewDownloader.py", line 57, in fill_queue
    queue = Util.fetch_json(DATA_URL)
  File "/usr/lib/python3.9/site-packages/variety/Util.py", line 644, in fetch_json
    return Util.request(url, data, **request_kwargs).json()
  File "/usr/lib/python3.9/site-packages/variety/Util.py", line 614, in request
    r = requests.request(
  File "/usr/lib/python3.9/site-packages/requests/api.py", line 61, in request
    return session.request(method=method, url=url, **kwargs)
  File "/usr/lib/python3.9/site-packages/requests/sessions.py", line 542, in request
    resp = self.send(prep, **send_kwargs)
  File "/usr/lib/python3.9/site-packages/requests/sessions.py", line 655, in send
    r = adapter.send(request, **kwargs)
  File "/usr/lib/python3.9/site-packages/requests/adapters.py", line 516, in send
    raise ConnectionError(e, request=request)
requests.exceptions.ConnectionError: HTTPSConnectionPool(host='raw.githubusercontent.com', port=443): Max retries exceeded with url: /limhenry/earthview/3cd868a932cd652c4373c0f6ea8618a96b08be4e/wallpaper%20changer/data.json (Caused by NewConnectionError('<urllib3.connection.HTTPSConnection object at 0x7f8af26a5280>: Failed to establish a new connection: [Errno -2] Name or service not known'))

(gtk-launch:11530): Gtk-WARNING **: 08:43:41.997: Theme parsing error: gtk-dark.css:6342:10: 'height' is not a valid property name

(firefox:11536): Gtk-WARNING **: 08:43:42.174: Theme parsing error: gtk-dark.css:6342:10: 'height' is not a valid property name

(/usr/lib/firefox/firefox:11642): Gtk-WARNING **: 08:43:42.984: Theme parsing error: gtk-dark.css:6342:10: 'height' is not a valid property name

(firefox:11536): Gtk-WARNING **: 08:43:42.986: Theme parsing error: gtk.css:6342:10: 'height' is not a valid property name

(firefox:11536): Gtk-WARNING **: 08:43:43.055: Theme parsing error: gtk.css:6342:10: 'height' is not a valid property name

(firefox:11536): Gtk-WARNING **: 08:43:43.087: Theme parsing error: gtk-dark.css:6342:10: 'height' is not a valid property name

(/usr/lib/firefox/firefox:11666): Gtk-WARNING **: 08:43:43.261: Theme parsing error: gtk-dark.css:6342:10: 'height' is not a valid property name

(/usr/lib/firefox/firefox:11717): Gtk-WARNING **: 08:43:43.611: Theme parsing error: gtk-dark.css:6342:10: 'height' is not a valid property name

(/usr/lib/firefox/firefox:11791): Gtk-WARNING **: 08:43:44.459: Theme parsing error: gtk-dark.css:6342:10: 'height' is not a valid property name

###!!! [Parent][RunMessage] Error: Channel closing: too late to send/recv, messages will be lost

kdeinit5: Got EXEC_NEW '/usr/lib/qt/plugins/kf5/kio/tags.so' from launcher.
kdeinit5: preparing to launch '/usr/lib/qt/plugins/kf5/kio/tags.so'

(chromium:12824): Gtk-WARNING **: 08:45:02.749: Theme parsing error: gtk-dark.css:6342:10: 'height' is not a valid property name
Fontconfig error: Cannot load default config file: No such file: (null)
libva error: /usr/lib/dri/i965_drv_video.so init failed
[12853:12853:0427/084503.022454:ERROR:sandbox_linux.cc(374)] InitializeSandbox() called with multiple threads in process gpu-process.
kdeinit5: PID 3296 terminated.
kdeinit5: PID 12779 terminated.
